Workbook

Sheet Attractions
A1: id | B1: name | C1: district | D1: coordinates | E1: category | F1: vibes | G1: environmental_tags | H1: demographic_tags | I1: summary_desc | J1: facilities_desc | K1: tips_desc
A2: acwd001 | B2: Kennedy Town New Praya | C2: =IF($A2<>"", _xlfn.IFNA(VLOOKUP(RIGHT(LEFT($A2,4),3),'District LookUp Table'!$A$2:$B$19,2,FALSE), "NOT FOUND"), "") -> Central & Western | D2: 22.283587, 114.125840 | E2: Nature & Scenary | F2: Local Favorites | G2: Outdoor | H2: Tourist Friendly | I2: Kennedy Town New Praya is a charming neighborhood blending vintage architecture with modern amenities, offering a balance of history and contemporary life. It’s a popular spot for locals and tourists alike, providing a relaxed atmosphere with waterfront views and diverse dining options. | J2: The location offers MTR access via the Kennedy Town station. A short walk leads to the Kennedy Town basketball court, offering a vantage point for observing the harbor. There is a %Arabica coffee shop with a grand view to the harbor. The area is also known for its local eateries and hip coffee shops. Walking along the waterfront is a popular activity. | K2: For a truly local experience, explore the Kennedy Town area. Enjoy the diverse dining options and the waterfront views. Be mindful of the area during peak hours to avoid crowds.
A3: acwd002 | B3: Sai Wan Swimming Shed | C3: =IF($A3<>"", _xlfn.IFNA(VLOOKUP(RIGHT(LEFT($A3,4),3),'District LookUp Table'!$A$2:$B$19,2,FALSE), "NOT FOUND"), "") -> Central & Western | D3: 22.2798456, 114.1175181 | E3: Nature & Scenery | F3: Chill, Insta-Worthy | G3: Outdoor | H3: Tourist Friendly, Couples | I3: A beautiful lookout for sunset views, offering stunning coastal scenery and a chance to capture iconic views. | J3: The location offers a wooden pier for walking and exploring. There are two staircases leading down to the pier, guiding you directly to the pier. | K3: Enjoy the sunset from the wooden pier. Take the stairs down to the pier for a unique experience. Be aware that the location can be popular, so expect a short wait for photos.
A4: acwd003 | B4: Sunset Seaview Pavillion | C4: =IF($A4<>"", _xlfn.IFNA(VLOOKUP(RIGHT(LEFT($A4,4),3),'District LookUp Table'!$A$2:$B$19,2,FALSE), "NOT FOUND"), "") -> Central & Western | D4: 22.2741043, 114.1171927 | E4: Nature & Scenery | F4: Chill | G4: Outdoor, Scenic | H4: Tourist Friendly | I4: Hong Kong offers a tranquil spot to witness stunning sunsets, particularly in a secluded area with limited crowds. A short walk down a staircase leads to a pavilion offering unobstructed views. Nearby, a large boat passage can be observed. | J4: The location offers a scenic view and is easily accessible via a 5B bus station. A short walk down the stairs leads to a viewpoint. There are multiple levels of stairs, with the UChicago campus accessible via a short walk. | K4: Be mindful of snakes roaming around the area, particularly on the path down to the pavilion. Wear protective gear against insects. The stairs can be slippery, so exercise caution.
A5: acwd004 | B5: Hong Kong Observation Wheel | C5: =IF($A5<>"", _xlfn.IFNA(VLOOKUP(RIGHT(LEFT($A5,4),3),'District LookUp Table'!$A$2:$B$19,2,FALSE), "NOT FOUND"), "") -> Central & Western | D5: 22.285354, 114.161736 | E5: Recreation & Activities | F5: Local Favorites, Insta-Worthy | G5: Budget | H5: Tourist Friendly, Couples, Family Friendly, Elderly Friendly, Pet Friendly | I5: The Hong Kong Observation Wheel is a lovely spot to enjoy the skyline, both day and night. The location is perfect — right by Victoria Harbour — offering panoramic views of Hong Kong Island, Kowloon, and the surrounding lights. | J5: The ride is smooth and lasts around 15 minutes, giving you enough time to enjoy the scenery and take photos. The cabins are air-conditioned and comfortable, making it pleasant even on warm days. Staff are friendly and the ticket price is reasonable compared to the experience. It’s great for families, couples, or anyone who loves city views. | K5: If you're in Hong Kong, even just for a few hours, this is a fun and easy way to take in the city from above. Definitely recommend i!t
A6: acwd005 | B6: Barker Road Viewing Point | C6: =IF($A6<>"", _xlfn.IFNA(VLOOKUP(RIGHT(LEFT($A6,4),3),'District LookUp Table'!$A$2:$B$19,2,FALSE), "NOT FOUND"), "") -> Central & Western | D6: 22.271291, 114.157525 | E6: Nature & Scenery | F6: Insta-Worthy, Hidden | G6: Outdoor | H6: Tourist Friendly, Solo Travelers | I6: Barker Road Viewing Point offers breathtaking panoramic views of Victoria Harbour, particularly popular with cyclists and motorcyclists. The location is a vibrant spot for capturing scenic moments and connecting with fellow enthusiasts. While traffic can occasionally disrupt the tranquility, the overall atmosphere is excellent. | J6: The viewing point offers direct access to the Victoria Harbor view. There is a roadside photo opportunity with a magnificent harbor view. A short cycling route is available from Admiralty to the Peak, offering less traffic and a more peaceful experience. The area is accessible by bicycle and offers a scenic route through the quick road. | K6: For optimal views, arrive early in the morning or late in the afternoon to avoid peak traffic. Bring a camera to capture the stunning scenery. Consider cycling to the Peak for a quieter experience.
A7: acwd006 | B7: Hong Kong Museum of Medical Sciences | C7: =IF($A7<>"", _xlfn.IFNA(VLOOKUP(RIGHT(LEFT($A7,4),3),'District LookUp Table'!$A$2:$B$19,2,FALSE), "NOT FOUND"), "") -> Central & Western | D7: 22.283415, 114.148558 | E7: Heritage & Culture | F7: Local Favorites | G7: Indoor | H7: Tourist Friendly, Family Friendly | I7: The Hong Kong Museum of Medical Sciences is a historical museum showcasing the evolution of medical science in Hong Kong, from the 19th century to the present day. It offers a comprehensive look at the history of medical practices, equipment, and research, including exhibits on the history of the plague, early medical techniques, and the development of Chinese medicine. The museum’s location in the Mid Levels of Hong Kong provides a unique setting, blending Western and traditional architectural elements. | J7: The museum features a large exhibition hall with interactive exhibits, including a simulated surgery experience, a display of medical equipment, and a presentation on the history of the plague. There is also a dedicated area for Chinese medicine exhibits, including a 3D Acu-Man exhibition. | K7: To get the best experience, take the MTR to Sheung Wan or Sai Ying Pun stations. The museum is open Tuesday to Saturday, 10 am to 5 pm, and Sunday and public holidays are open until 5 pm. Be prepared for a walk up a hill to reach the museum.
A8: acwd007 | B8: Lan Kwai Fong | C8: =IF($A8<>"", _xlfn.IFNA(VLOOKUP(RIGHT(LEFT($A8,4),3),'District LookUp Table'!$A$2:$B$19,2,FALSE), "NOT FOUND"), "") -> Central & Western | D8: 22.280879, 114.155398 | E8: Recreation & Activities | F8: Chill | G8: Indoor | H8: Tourist Friendly, Solo Travelers | I8: Lan Kwai Fong is a vibrant, energetic hub in Hong Kong's Central district, known for its diverse range of bars, clubs, and restaurants. It's a popular destination for tourists and locals alike, offering a lively atmosphere and a wide selection of entertainment. The area is known for its pubs, and a historic prison is located nearby. | J8: The area boasts a wide array of amenities, including numerous bars, nightclubs, cocktail bars, and restaurants. Visitors can easily access MTR stations, including Central Station Exit D1, and walk along Pedder Street and Wyndham Street. Taxi services are readily available. There are also art galleries and restaurants to visit during the day. | K8: For a truly immersive experience, explore the area after 9:30 PM, especially on Friday and Saturday nights. Be prepared for crowds and a high level of energy. If you're looking for a relaxing evening, consider visiting during the day to explore the local art galleries and restaurants. Be aware of the potential for sleazy behavior and prioritize your safety. Enjoy the vibrant nightlife and embrace the local culture.
A9: acwd008 | B9: Tai Kwun | C9: =IF($A9<>"", _xlfn.IFNA(VLOOKUP(RIGHT(LEFT($A9,4),3),'District LookUp Table'!$A$2:$B$19,2,FALSE), "NOT FOUND"), "") -> Central & Western | D9: 22.281552, 114.154078 | E9: Heritage & Culture | F9: Retro/Nostalgic | G9: Indoor, Budget | H9: Tourist Friendly, Family Friendly | I9: Tai Kwun, a heritage-arts venue and living record of the legal system in Hong Kong, offers a unique blend of history, art, and culture. Located in Central, it features 16 revitalized buildings, including the former Central Police Station and Magistracy, and is home to interactive exhibits and a diverse range of activities. Visitors can explore the justice system history, enjoy a mix of art, music, and theatre, and experience a vibrant atmosphere. | J9: Tai Kwun offers a variety of facilities, including shops, restaurants, exhibitions, and interactive exhibits. The complex includes 3 major heritage properties: Former Central Police Station, Former Central Magistracy, and Former Victoria Prison. Visitors can explore the former Central Police Station, the former Central Magistracy, and the former Victoria Prison, all declared monuments in Hong Kong. The complex includes a large space for exhibitions, and a variety of food and drink outlets. The complex includes a new JC Contemporary also within the compound. | K9: Visit the museum to learn about the history of the legal system and the justice system. Take a walk around the complex to see the different buildings and historical sites. Be sure to allow ample time to explore the different sections and attractions. The complex is large, so plan your route in advance.
A10: acwd009 | B10: Central Market | C10: =IF($A10<>"", _xlfn.IFNA(VLOOKUP(RIGHT(LEFT($A10,4),3),'District LookUp Table'!$A$2:$B$19,2,FALSE), "NOT FOUND"), "") -> Central & Western | D10: 22.284051, 114.155443 | E10: Urban & Architecture | F10: Local Favorites, Retro/Nostalgic | G10: Indoor | H10: Tourist Friendly, Family Friendly, Solo Travelers, Elderly Friendly | I10: Hong Kong's historic street market, once a bustling commercial hub, has been revitalized into a vibrant and engaging public space. This landmark, preserved as a 'Playground For All', now offers a unique blend of traditional heritage and modern design, attracting visitors seeking a memorable cultural experience. | J10: The market features numerous food stalls, artisanal shops, and cafes. There are several shops selling unique clothing, jewelry, and handmade goods. The ground floor offers a variety of dining options and drinks. The upper floors house exhibition spaces and quirky shops like Tiny HK. A quick link to the mid-levels escalator is readily available. | K10: Explore the market's diverse offerings, from local street food to handcrafted goods. Take your time to wander through the stalls and soak in the atmosphere. Don't be afraid to strike up conversations with vendors and locals. Enjoy a leisurely meal and a refreshing drink.
A11: acwd010 | B11: Hong Kong Zoological and Botanical Gardens | C11: =IF($A11<>"", _xlfn.IFNA(VLOOKUP(RIGHT(LEFT($A11,4),3),'District LookUp Table'!$A$2:$B$19,2,FALSE), "NOT FOUND"), "") -> Central & Western | D11: 22.277695, 114.156412 | E11: Recreation & Activities | F11: Chill, Local Favorites | G11: Outdoor, Free | H11: Family Friendly, Solo Travelers | I11: The Hong Kong Zoological and Botanical Gardens is a free to enter park and botanical garden in Hong Kong, offering a peaceful escape in the heart of the city while promoting education and conservation efforts. It features a diverse range of plants and animals, including primates, birds, and mammals, and provides a unique experience for families, tourists, and nature enthusiasts. The park is known for its beautiful greenery, wildlife, and accessible pathways. | J11: The park offers a variety of facilities, including walking paths, arboretum, and a green house. Visitors can enjoy walking around before getting on the Peak tram, observing animals and birds, and relaxing in the peaceful atmosphere. The park is hilly, so come rested. | K11: Visit during mornings and afternoons for quieter experiences. The zoo is free, and it's a great place to explore different species of animals and plants. The park is a great place to relax and escape the hustle and bustle of the city.
A12: aead001 | B12: Monster Building Spot | C12: =IF($A12<>"", _xlfn.IFNA(VLOOKUP(RIGHT(LEFT($A12,4),3),'District LookUp Table'!$A$2:$B$19,2,FALSE), "NOT FOUND"), "") -> Eastern | D12: 22.284277, 114.212469 | E12: Urban & Architecture | F12: Insta-Worthy | G12: Urban | H12: Tourist Friendly, Family Friendly | I12: The Monster Building in Quarry Bay is a striking example of high-density urban living in Hong Kong, featuring a complex of five interconnected apartments. Originally built in the 1960s as a common home, it has become an iconic photography and film location, frequently featured in Hollywood movies. It’s a popular destination for architecture enthusiasts and urban explorers, with over 2,200 apartment units and thousands of residents. | J12: Free of charge, with two entrances on King’s Road. Accessible by subway, bus, taxi, or ding ding. | K12: Allow 30 minutes to take pictures without disturbing locals. Support the locals by visiting cafes and stores in the complex. Do not disturb the locals as this is their living place.
A13: aead002 | B13: Chun Yeung Street | C13: =IF($A13<>"", _xlfn.IFNA(VLOOKUP(RIGHT(LEFT($A13,4),3),'District LookUp Table'!$A$2:$B$19,2,FALSE), "NOT FOUND"), "") -> Eastern | D13: 22.291335, 114.197828 | E13: Urban & Architecture | F13: Local Favorites | G13: Outdoor, Urban | H13: Tourist Friendly | I13: This location offers a unique experience with a wet market and tram views, particularly popular for photographers. It’s a vibrant, bustling area with a strong local atmosphere. | J13: The location features a wet market with shops and stalls, and a tramway passing through the market. MTR exit: North Point station A1 or eastbound tram heading towards the North Point terminus. | K13: Be prepared for crowds, especially during peak hours, and consider bringing cash as prices may be higher than other markets. Enjoy the atmosphere and capture some memorable photos.
... A15: aead004 | B15: Lei Yue Mun Park | C15: =IF($A15<>"", _xlfn.IFNA(VLOOKUP(RIGHT(LEFT($A15,4),3),'District LookUp Table'!$A$2:$B$19,2,FALSE), "NOT FOUND"), "") -> Eastern | D15: 22.277737, 114.232659 | E15: Nature & Scenery | F15: Chill | G15: Outdoor, Steep Terrain | H15: Family Friendly, Tourist Friendly | I15: Lei Yue Mun Park is a large park with a playground, archery, karaoke, and a horse riding school. It offers a scenic outdoor space with a steep hill. | J15: Playground, Archery, Karaoke room, Bicycle rental, Board games, Bracelet making workshop, BBQ facilities, Horseback riding school, canteen. | K15: Bring mosquito repellent, wear comfortable shoes for steep slopes, and bring your own drinks to save money. Be prepared for pricey vending machine drinks and the strict coach at the archery range.
A16: aead005 | C16: =IF($A16<>"", _xlfn.IFNA(VLOOKUP(RIGHT(LEFT($A16,4),3),'District LookUp Table'!$A$2:$B$19,2,FALSE), "NOT FOUND"), "") -> Eastern
A17: aisd001 | B17: Pui O Beach | C17: =IF($A17<>"", _xlfn.IFNA(VLOOKUP(RIGHT(LEFT($A17,4),3),'District LookUp Table'!$A$2:$B$19,2,FALSE), "NOT FOUND"), "") -> Islands | D17: 22.238876, 113.978691 | E17: Recreation & Activities | F17: Chill, Local Favorites | G17: Outdoor | H17: Tourist Friendly | I17: Pui O Beach, located on the south side of Lantau Island, offers a relaxing experience with a mix of black and yellow sand, a popular weekend destination, and opportunities for swimming, camping, and exploring the surrounding landscape. | J17: Facilities include Beach, Lifeguard Station, Beach Shack Cafe, Rental, and Camping. | K17: Visit during the off-season for fewer crowds. Bring sunscreen and a hat. Be mindful of the mud on the beach. Check the beach's status before heading there. Enjoy the scenic views and the local culture.
A18: aisd002 | B18: Tai O | C18: =IF($A18<>"", _xlfn.IFNA(VLOOKUP(RIGHT(LEFT($A18,4),3),'District LookUp Table'!$A$2:$B$19,2,FALSE), "NOT FOUND"), "") -> Islands | D18: 22.254151, 113.862149 | E18: Nature & Scenary | F18: Local Favorites, Hidden | G18: Outdoor | H18: Tourist Friendly | I18: Tai O is a charming fishing village in Hong Kong, offering a glimpse into traditional life. Located near the Big Buddha, it features stilts over the water and a unique atmosphere. Visitors can easily access the village via bus from the Big Buddha and ca, and enjoy boat rides to see pink dolphins. The village is known for its fish products, curried fish balls, and local sauces. | J18: Bus services connect Tai O to the Big Buddha. Boat rides are available to see pink dolphins. | K18: Explore the village on foot, try the local curried fish balls and sauces, and take advantage of the boat rides to see the pink dolphins. Be prepared for a slower pace of travel due to the village's size.
A19: aisd003 | B19: Citygate Outlets | C19: =IF($A19<>"", _xlfn.IFNA(VLOOKUP(RIGHT(LEFT($A19,4),3),'District LookUp Table'!$A$2:$B$19,2,FALSE), "NOT FOUND"), "") -> Islands | D19: 22.289652, 113.941258 | E19: Shopping | F19: Local Favorites | G19: Indoor | H19: Tourist Friendly | I19: Citygate Outlets is a large shopping mall located near an airport, offering a wide variety of retail outlets, food options, and amenities. It features air conditioning, numerous shops, and convenient transportation links to the city center. | J19: The mall features MTR exits, bus routes, and ample space for walking. There are restrooms available. Nearby apartments are also available for those needing a place to stay. | K19: For efficient travel, utilize the MTR station nearby. Be prepared for crowds, especially during peak hours. Check for deals and promotions on various shops.
A20: aisd004 | C20: =IF($A20<>"", _xlfn.IFNA(VLOOKUP(RIGHT(LEFT($A20,4),3),'District LookUp Table'!$A$2:$B$19,2,FALSE), "NOT FOUND"), "") -> Islands
A21: aisd005 | C21: =IF($A21<>"", _xlfn.IFNA(VLOOKUP(RIGHT(LEFT($A21,4),3),'District LookUp Table'!$A$2:$B$19,2,FALSE), "NOT FOUND"), "") -> Islands
A22: akcd001 | B22: Lung Cheung Road Sitting-out Area | C22: =IF($A22<>"", _xlfn.IFNA(VLOOKUP(RIGHT(LEFT($A22,4),3),'District LookUp Table'!$A$2:$B$19,2,FALSE), "NOT FOUND"), "") -> Kowloon City | D22: 22.342497, 114.174208 | E22: Nature & Scenery | F22: Insta-Worthy, Scenic | G22: Outdoor | H22: Tourist Friendly, Solo Travelers | I22: The Lung Cheung Road Observatory is a small location offering panoramic city views. It provides a stunning vista of the skyline framed by mountains and greenery, particularly impressive during both daytime and nighttime. The area is known for its unobstructed views and peaceful atmosphere. Visitors can easily access this vantage point. | J22: The Lung Cheung Road Observatory offers sweeping, unobstructed views of the city skyline. Transportation options include taking a bus directly to the Phoenix House stop, or a 15-minute uphill walk from the Moonbeam Terrace bus stop. | K22: Bring a camera to capture the stunning views. Consider visiting after dark for the best nighttime panorama. Be prepared for a slightly challenging uphill walk if taking the bus route alighting at Moonbeam Terrace.
A23: akcd002 | B23: Kowloon Walled City Park | C23: =IF($A23<>"", _xlfn.IFNA(VLOOKUP(RIGHT(LEFT($A23,4),3),'District LookUp Table'!$A$2:$B$19,2,FALSE), "NOT FOUND"), "") -> Kowloon City | E23: Heritage & Culture | F23: Hidden, Local Favorites | G23: Outdoor | H23: Tourist Friendly, Solo Travelers, Elderly Friendly | I23: Kowloon Walled Park is a historical park in Hong Kong, representing a unique territory with a complex past. The park incorporates restored former houses and offers a glimpse into the city's history. It provides a peaceful escape from the city's bustle, featuring landscaped gardens and traditional Chinese design. The park’s size is considerable, offering ample space for exploration and relaxation. | J23: Visitors can access the park by taking the subway to Sung Wong Toi then exit from B3, then walking two gates. A free exhibition from the movie Walled in, twilight of the warriors is available, but requires timed tickets. The park includes a basketball court, soccer court, and a cycling area. Traditional Chinese garden design, winding paths, ponds, and pavilions are present within the park. | K23: Walled in exhibition is free. Consider visiting during quieter times to avoid crowds and enjoy a more peaceful experience. The park is well-maintained and offers a pleasant walking experience.
A24: akcd003 | B24: Kai Tak Sports Park | C24: =IF($A24<>"", _xlfn.IFNA(VLOOKUP(RIGHT(LEFT($A24,4),3),'District LookUp Table'!$A$2:$B$19,2,FALSE), "NOT FOUND"), "") -> Kowloon City | E24: Recreation & Activities | F24: Chill, Insta-Worthy | G24: Outdoor | H24: Tourist Friendly, Family Friendly, Solo Travelers | I24: Kai Tak Sports Park is a large open space developed from the former Kai Tak Airport Grounds. It encompasses sports facilities, residential towers, restaurants, and malls, spanning a significant area between Sung Wong Toi and Kai Tak MTR Stations. The park features a 10,000-capacity sports ground and a 50,000-seat stadium. The area offers a blend of recreational activities, shopping, and dining options, creating a vibrant and modern atmosphere. | J24: Visitors can access the park by exiting Kai Tak Station on the Tuen Ma Line. It involves a considerable walk due to the expansive area. The park includes large-scale sculptures, fountain pools, benches, and covered walkways for shade and protection from the elements. Several malls are located around the area, offering a variety of food choices. Public toilets are available within the area. The waterfront is beginning to open, utilizing the old airport runway and extending to the adjacent cruise terminal. | K24: Visitors should be prepared for a long walk from the MTR exits. The malls are good places to cool down on hot summer days. Locals frequently visit the park for walks and dog-walking.
A25: akcd004 | C25: =IF($A25<>"", _xlfn.IFNA(VLOOKUP(RIGHT(LEFT($A25,4),3),'District LookUp Table'!$A$2:$B$19,2,FALSE), "NOT FOUND"), "") -> Kowloon City
A26: akcd005 | C26: =IF($A26<>"", _xlfn.IFNA(VLOOKUP(RIGHT(LEFT($A26,4),3),'District LookUp Table'!$A$2:$B$19,2,FALSE), "NOT FOUND"), "") -> Kowloon City
A27: aktd001 | B27: Laguna Park | C27: =IF($A27<>"", _xlfn.IFNA(VLOOKUP(RIGHT(LEFT($A27,4),3),'District LookUp Table'!$A$2:$B$19,2,FALSE), "NOT FOUND"), "") -> Kwun Tong | E27: Nature & Scenery | F27: Chill, Local Favorites | G27: Outdoor | H27: Family Friendly, Elderly Friendly, Solo Travelers | I27: Laguna Park is a large neighborhood park situated adjacent to Laguna City, serving a residential community of over 20,000 people. It offers a green space for recreation and relaxation, featuring jogging tracks and fitness equipment. The park’s origins date back to 1991 as part of a housing development marketing campaign. While functional, it doesn’t offer extraordinary features and can be crowded during peak times. | J27: The park includes a children’s playground, jogging track, fitness equipment, benches, public restrooms, and smaller water fountains. There are trees providing shade. Access to the park is available via local residential streets. | K27: Ask the staff to heat up your pastry, and avoid visiting during peak hours if you dislike loud music.
A28: aktd002 | B28: Jordan Valley Park | C28: =IF($A28<>"", _xlfn.IFNA(VLOOKUP(RIGHT(LEFT($A28,4),3),'District LookUp Table'!$A$2:$B$19,2,FALSE), "NOT FOUND"), "") -> Kwun Tong | E28: Recreation & Activities | F28: Chill, Local Favorites | G28: Outdoor | H28: Tourist Friendly, Family Friendly, Solo Travelers | I28: Jordan Valley Park is a large park offering green spaces and recreational activities. It features expansive lawns, a model car racing track, and a family-friendly climbing trail. The park provides a relaxing escape from the city, with well-maintained facilities and ample space for various activities. It’s a popular spot for families and individuals seeking outdoor recreation. | J28: The park has two central lawns suitable for running and relaxing, and it includes running trails with varying routes and inclines. There is a remote car circuit for children to enjoy, and the Jordan Valley Morning Trail provides a family-friendly climbing experience. The park also offers a car park. | K28: Ask the staff to heat up your pastry, and avoid visiting during peak hours if you dislike loud music. The car park can be limited, and visitors may need to park at the police apartments if it is full.
A29: aktd003 | C29: =IF($A29<>"", _xlfn.IFNA(VLOOKUP(RIGHT(LEFT($A29,4),3),'District LookUp Table'!$A$2:$B$19,2,FALSE), "NOT FOUND"), "") -> Kwun Tong
A30: aktd004 | C30: =IF($A30<>"", _xlfn.IFNA(VLOOKUP(RIGHT(LEFT($A30,4),3),'District LookUp Table'!$A$2:$B$19,2,FALSE), "NOT FOUND"), "") -> Kwun Tong
A31: aktd005 | C31: =IF($A31<>"", _xlfn.IFNA(VLOOKUP(RIGHT(LEFT($A31,4),3),'District LookUp Table'!$A$2:$B$19,2,FALSE), "NOT FOUND"), "") -> Kwun Tong
A32: akwd001 | B32: Central Kwai Chung Park | C32: =IF($A32<>"", _xlfn.IFNA(VLOOKUP(RIGHT(LEFT($A32,4),3),'District LookUp Table'!$A$2:$B$19,2,FALSE), "NOT FOUND"), "") -> Kwai Tsing | E32: Nature & Scenery | F32: Hidden, Local Favorites | G32: Outdoor | H32: Tourist Friendly, Family Friendly, Solo Travelers | I32: Central Kwai Chung Park is a hidden park located in the industrial district of Hong Kong. It offers walking trails, sports courts, and shaded areas, providing a peaceful escape from the urban environment. The park boasts rich biodiversity and interesting historical features. It’s an oasis of nature within the city. | J32: The park offers functional facilities, including two water dispensers and toilets. However, the walls on the sports courts are noted to be quite short. There are many little paths and places to explore within the park. | K32: Avoid visiting during peak hours if you dislike loud music. Be aware of mosquitoes and consider bringing repellent. The park is suitable for easy hiking and jogging.
A33: akwd002 | B33: Kwai Chung Plaza | C33: =IF($A33<>"", _xlfn.IFNA(VLOOKUP(RIGHT(LEFT($A33,4),3),'District LookUp Table'!$A$2:$B$19,2,FALSE), "NOT FOUND"), "") -> Kwai Tsing | E33: Shopping | F33: Bustling, Local Favorites | G33: Indoor | H33: Tourist Friendly, Solo Travelers, Budget | I33: Kwai Chung Plaza is a small, unique shopping venue located outside the Kwai Fong MTR Station. It offers a vibrant and lively atmosphere with hundreds of small, locally-owned shops and kiosks. The plaza is known for its budget-friendly prices and a diverse selection of goods, reminiscent of shopping in Southeast Asian cities. It’s a bustling and welcoming space for shoppers seeking a different experience. | J33: Kwai Chung Plaza is an indoor shopping venue accessible via the Kwai Fong MTR Station (exit D). The property opened in 1990 and features multiple floors, offering a variety of shops and eateries. There are several floors with food shops and a level selling fresh food such as vegetables and fruits. The plaza can be incredibly crowded, and while some recognizable brand name retailers and casual eateries are present, most of the businesses are locally owned. Taxi availability is assumed, but specific details are not mentioned. | K33: Be prepared for crowds and potential noise. Haggling is expected when shopping at the kiosks. This plaza offers a unique shopping experience, reminiscent of Southeast Asian markets, and is a good option for budget-conscious shoppers.
A34: akwd003 | C34: =IF($A34<>"", _xlfn.IFNA(VLOOKUP(RIGHT(LEFT($A34,4),3),'District LookUp Table'!$A$2:$B$19,2,FALSE), "NOT FOUND"), "") -> Kwai Tsing
A35: akwd004 | C35: =IF($A35<>"", _xlfn.IFNA(VLOOKUP(RIGHT(LEFT($A35,4),3),'District LookUp Table'!$A$2:$B$19,2,FALSE), "NOT FOUND"), "") -> Kwai Tsing
A36: akwd005 | C36: =IF($A36<>"", _xlfn.IFNA(VLOOKUP(RIGHT(LEFT($A36,4),3),'District LookUp Table'!$A$2:$B$19,2,FALSE), "NOT FOUND"), "") -> Kwai Tsing
A37: anod001 | B37: Sha Tau Kok | C37: =IF($A37<>"", _xlfn.IFNA(VLOOKUP(RIGHT(LEFT($A37,4),3),'District LookUp Table'!$A$2:$B$19,2,FALSE), "NOT FOUND"), "") -> North | E37: Nature & Scenery | F37: Insta-Worthy, Hidden | G37: Outdoor | H37: Tourist Friendly, Solo Travelers | I37: Located at the border between the North District of the New Territories in Hong Kong and the Yantian District of Shenzhen in the Mainland, Sha Tau Kok was once a Frontier Closed Area. Following its opening, it has now become a popular destination for day trips, requiring a Closed Area Permit for entry. The first and second phases of Sha Tau Kok Pier have opened, providing transportation options for both individual travelers and day-trip tour groups. The area features spectacular coastlines and unique historical landmarks, such as vintage road signs and the Sun Moon Pavilion. Sha Tau Kok is renowned for its beautiful sea views and cultural history. | J37: Sha Tau Kok Pier is 280 meters long; originally built in the 1960s and later reconstructed in 2004, it is only a 20 to 30-minute boat ride from Kat O and Ap Chau. The pier promenade is a choice for romantic strolls. At the end of the pier, "The Ends of the Earth" paired with a pure white lighthouse offers beautiful scenery. Shun Ping Street features murals on the walls painted by Sha Tau Kok primary school students. At the end of the pier, "The Ends of the Earth" paired with a pure white lighthouse offers beautiful scenery. The Old Sha Tau Kok Fire Station is a distinctive landmark of Sha Tau Kok, preserving its former appearance and displaying a 1:1 replica of a century-old hand-drawn fire engine. Chung Ying Street is located at the border and was once a trading center for Hong Kong merchants during the early Reform and Opening-up period; it is now a site of historical witness, featuring a wishing lookout and a garden modeled after the style of old Hong Kong railway stations. | K37: Apply for a Closed Area Permit to visit Sha Tau Kok. Kaito ferries are available to reach tourist hotspots such as Lai Chi Wo, Kat O, and Ap Chau. Consider avoiding peak hours to avoid crowds. Sha Tau Kok Pier offers a romantic walking route, featuring murals by Sha Tau Kok primary school students on the walls. Enjoy the lighthouse and sea views at "The Ends of the Earth." The Old Sha Tau Kok Fire Station displays a vintage fire engine and is a great spot for photos. Chung Ying Street Garden provides an opportunity to view Chung Ying Street and allows for hanging wishing plaques.
A38: anod002 | B38: Long Valley Nature Centre | C38: =IF($A38<>"", _xlfn.IFNA(VLOOKUP(RIGHT(LEFT($A38,4),3),'District LookUp Table'!$A$2:$B$19,2,FALSE), "NOT FOUND"), "") -> North
A39: anod003 | C39: =IF($A39<>"", _xlfn.IFNA(VLOOKUP(RIGHT(LEFT($A39,4),3),'District LookUp Table'!$A$2:$B$19,2,FALSE), "NOT FOUND"), "") -> North
A40: anod004 | C40: =IF($A40<>"", _xlfn.IFNA(VLOOKUP(RIGHT(LEFT($A40,4),3),'District LookUp Table'!$A$2:$B$19,2,FALSE), "NOT FOUND"), "") -> North
A41: anod005 | C41: =IF($A41<>"", _xlfn.IFNA(VLOOKUP(RIGHT(LEFT($A41,4),3),'District LookUp Table'!$A$2:$B$19,2,FALSE), "NOT FOUND"), "") -> North
...

Sheet Restaurants
A1: id | B1: name | C1: district | D1: coordinates | E1: type | F1: cuisine | G1: famous_dish | H1: price_level | I1: opening_time | J1: description | K1: transport
A2: ryld001 | B2: Wing Shun Restaurant | C2: =IF(A2<>"", _xlfn.IFNA(VLOOKUP(RIGHT(LEFT(A2,4),3),'District LookUp Table'!$A$2:$B$19,2,FALSE), "NOT FOUND"), "") -> Yuen Long | E2: Cha Chaan Teng | F2: Hong Kong | G2: Satay Beef Noodle | H2: 51-100 | I2: 0630-1730 | K2: MTR, Bus, Light Rail
A3: ryld002 | B3: LokWu Noodles | C3: =IF(A3<>"", _xlfn.IFNA(VLOOKUP(RIGHT(LEFT(A3,4),3),'District LookUp Table'!$A$2:$B$19,2,FALSE), "NOT FOUND"), "") -> Yuen Long | E3: Restaurant | F3: Chinese | G3: Knife Cut Noodles | H3: 51-100 | I3: 1200-2200 | K3: Bus, Light Rail
A4: ryld003 | B4: 劉興記生煎包專門店 | C4: =IF(A4<>"", _xlfn.IFNA(VLOOKUP(RIGHT(LEFT(A4,4),3),'District LookUp Table'!$A$2:$B$19,2,FALSE), "NOT FOUND"), "") -> Yuen Long | E4: Restaurant | F4: Chinese | G4: Shengjian Mantou (Pan Fried Bun) | H4: 51-100 | I4: 1130-2030 | K4: Bus, Light Rail
A5: rtmd001 | B5: 雲川 | C5: =IF(A5<>"", _xlfn.IFNA(VLOOKUP(RIGHT(LEFT(A5,4),3),'District LookUp Table'!$A$2:$B$19,2,FALSE), "NOT FOUND"), "") -> Tuen Mun | E5: Restaurant | F5: Chinese | G5: Rice Noodles | H5: 51-100 | I5: 1100-2230 | K5: Bus, Light Rail
A6: rtmd002 | B6: 很得輝 | C6: =IF(A6<>"", _xlfn.IFNA(VLOOKUP(RIGHT(LEFT(A6,4),3),'District LookUp Table'!$A$2:$B$19,2,FALSE), "NOT FOUND"), "") -> Tuen Mun | E6: Snacks | F6: Hong Kong | G6: Fried Chicken | H6: <50 | I6: 1230-0200 | K6: Bus, Light Rail
A7: rtmd003 | B7: 1986正宗越南料理 VIETNAMESE RESTAURANT | C7: =IF(A7<>"", _xlfn.IFNA(VLOOKUP(RIGHT(LEFT(A7,4),3),'District LookUp Table'!$A$2:$B$19,2,FALSE), "NOT FOUND"), "") -> Tuen Mun | E7: Restaurant | F7: Vietnamese | G7: Pho (Vietnamese Noodle) | H7: 50-100 | I7: 1100-2030 | K7: MTR, Bus, Light Rail
A8: rtwd | C8: =IF(A8<>"", _xlfn.IFNA(VLOOKUP(RIGHT(LEFT(A8,4),3),'District LookUp Table'!$A$2:$B$19,2,FALSE), "NOT FOUND"), "") -> Tsuen Wan
C9: =IF(A9<>"", _xlfn.IFNA(VLOOKUP(RIGHT(LEFT(A9,4),3),'District LookUp Table'!$A$2:$B$19,2,FALSE), "NOT FOUND"), "")
C10: =IF(A10<>"", _xlfn.IFNA(VLOOKUP(RIGHT(LEFT(A10,4),3),'District LookUp Table'!$A$2:$B$19,2,FALSE), "NOT FOUND"), "")
C11: =IF(A11<>"", _xlfn.IFNA(VLOOKUP(RIGHT(LEFT(A11,4),3),'District LookUp Table'!$A$2:$B$19,2,FALSE), "NOT FOUND"), "")
C12: =IF(A12<>"", _xlfn.IFNA(VLOOKUP(RIGHT(LEFT(A12,4),3),'District LookUp Table'!$A$2:$B$19,2,FALSE), "NOT FOUND"), "")
C13: =IF(A13<>"", _xlfn.IFNA(VLOOKUP(RIGHT(LEFT(A13,4),3),'District LookUp Table'!$A$2:$B$19,2,FALSE), "NOT FOUND"), "")
C14: =IF(A14<>"", _xlfn.IFNA(VLOOKUP(RIGHT(LEFT(A14,4),3),'District LookUp Table'!$A$2:$B$19,2,FALSE), "NOT FOUND"), "")
C15: =IF(A15<>"", _xlfn.IFNA(VLOOKUP(RIGHT(LEFT(A15,4),3),'District LookUp Table'!$A$2:$B$19,2,FALSE), "NOT FOUND"), "")
C16: =IF(A16<>"", _xlfn.IFNA(VLOOKUP(RIGHT(LEFT(A16,4),3),'District LookUp Table'!$A$2:$B$19,2,FALSE), "NOT FOUND"), "")
C17: =IF(A17<>"", _xlfn.IFNA(VLOOKUP(RIGHT(LEFT(A17,4),3),'District LookUp Table'!$A$2:$B$19,2,FALSE), "NOT FOUND"), "")
C18: =IF(A18<>"", _xlfn.IFNA(VLOOKUP(RIGHT(LEFT(A18,4),3),'District LookUp Table'!$A$2:$B$19,2,FALSE), "NOT FOUND"), "")
C19: =IF(A19<>"", _xlfn.IFNA(VLOOKUP(RIGHT(LEFT(A19,4),3),'District LookUp Table'!$A$2:$B$19,2,FALSE), "NOT FOUND"), "")
C20: =IF(A20<>"", _xlfn.IFNA(VLOOKUP(RIGHT(LEFT(A20,4),3),'District LookUp Table'!$A$2:$B$19,2,FALSE), "NOT FOUND"), "")
... C50: =IF(A50<>"", _xlfn.IFNA(VLOOKUP(RIGHT(LEFT(A50,4),3),'District LookUp Table'!$A$2:$B$19,2,FALSE), "NOT FOUND"), "")

Sheet District LookUp Table
A1: id | B1: district
A2: cwd | B2: Central & Western
A3: ead | B3: Eastern
A4: isd | B4: Islands
A5: kcd | B5: Kowloon City
A6: ktd | B6: Kwun Tong
A7: kwd | B7: Kwai Tsing
A8: nod | B8: North
A9: skd | B9: Sai Kung
A10: std | B10: Sha Tin
A11: ssp | B11: Sham Shui Po
A12: sod | B12: Southern
... A19: yld | B19: Yuen Long

Sheet Tags
A1: Categories | B1: Vibe | C1: Environmental Tags | D1: Demographic Tags | E1: Budget
A2: Nature & Scenary | B2: Chill | C2: Outdoor | D2: Tourist Friendly | E2: Free
A3: Heritage & Culture | B3: Romantic | C3: Indoor | D3: Family Friendly | E3: <100
A4: Food & Drink | B4: Bustling | C4: Budget | D4: Couples | E4: 100-500
A5: Recreation & Activities | B5: Zen | C5: Free | D5: Solo Travelers | E5: >500
A6: Urban & Architecture | B6: Insta-Worthy | C6: Steep Terrain | D6: Elderly Friendly
A7: Shopping | B7: Retro/Nostalgic | C7: Urban | D7: Pet Friendly
A8: Religious & Spiritual | B8: Industrial
B9: Hidden
B10: Local Favorites
